Traceback (most recent call last):
  File "/opt/hostedtoolcache/Python/3.8.11/x64/lib/python3.8/site-packages/jupyter_cache/executors/utils.py", line 51, in single_nb_execution
    executenb(
  File "/opt/hostedtoolcache/Python/3.8.11/x64/lib/python3.8/site-packages/nbclient/client.py", line 1117, in execute
    return NotebookClient(nb=nb, resources=resources, km=km, **kwargs).execute()
  File "/opt/hostedtoolcache/Python/3.8.11/x64/lib/python3.8/site-packages/nbclient/util.py", line 78, in wrapped
    return just_run(coro(*args, **kwargs))
  File "/opt/hostedtoolcache/Python/3.8.11/x64/lib/python3.8/site-packages/nbclient/util.py", line 57, in just_run
    return loop.run_until_complete(coro)
  File "/opt/hostedtoolcache/Python/3.8.11/x64/lib/python3.8/asyncio/base_events.py", line 616, in run_until_complete
    return future.result()
  File "/opt/hostedtoolcache/Python/3.8.11/x64/lib/python3.8/site-packages/nbclient/client.py", line 558, in async_execute
    await self.async_execute_cell(
  File "/opt/hostedtoolcache/Python/3.8.11/x64/lib/python3.8/site-packages/nbclient/client.py", line 862, in async_execute_cell
    self._check_raise_for_error(cell, exec_reply)
  File "/opt/hostedtoolcache/Python/3.8.11/x64/lib/python3.8/site-packages/nbclient/client.py", line 765, in _check_raise_for_error
    raise CellExecutionError.from_cell_and_msg(cell, exec_reply_content)
nbclient.exceptions.CellExecutionError: An error occurred while executing the following cell:
------------------
import napari
import numpy as np
from skimage import data

# create vector data
n = 250
vectors = np.zeros((n, 2, 2), dtype=np.float32)
phi_space = np.linspace(0, 4 * np.pi, n)
radius_space = np.linspace(0, 100, n)
# assign x-y projection
vectors[:, 1, 0] = radius_space * np.cos(phi_space)
vectors[:, 1, 1] = radius_space * np.sin(phi_space)
# assign x-y position
vectors[:, 0] = vectors[:, 1] + 256

# add the image
viewer = napari.view_image(data.camera(), name='photographer')
# add the vectors
vectors_layer = viewer.add_vectors(vectors, edge_width=3)
------------------

[0;31m---------------------------------------------------------------------------[0m
[0;31mImportError[0m                               Traceback (most recent call last)
[0;32m/tmp/ipykernel_2151/2814492494.py[0m in [0;36m<module>[0;34m[0m
[1;32m      1[0m [0;32mimport[0m [0mnapari[0m[0;34m[0m[0;34m[0m[0m
[1;32m      2[0m [0;32mimport[0m [0mnumpy[0m [0;32mas[0m [0mnp[0m[0;34m[0m[0;34m[0m[0m
[0;32m----> 3[0;31m [0;32mfrom[0m [0mskimage[0m [0;32mimport[0m [0mdata[0m[0;34m[0m[0;34m[0m[0m
[0m[1;32m      4[0m [0;34m[0m[0m
[1;32m      5[0m [0;31m# create vector data[0m[0;34m[0m[0;34m[0m[0;34m[0m[0m

[0;32m/opt/hostedtoolcache/Python/3.8.11/x64/lib/python3.8/site-packages/skimage/__init__.py[0m in [0;36m<module>[0;34m[0m
[1;32m    133[0m                              [0mimg_as_bool[0m[0;34m,[0m[0;34m[0m[0;34m[0m[0m
[1;32m    134[0m                              dtype_limits)
[0;32m--> 135[0;31m     [0;32mfrom[0m [0;34m.[0m[0mdata[0m [0;32mimport[0m [0mdata_dir[0m[0;34m[0m[0;34m[0m[0m
[0m[1;32m    136[0m     [0;32mfrom[0m [0;34m.[0m[0mutil[0m[0;34m.[0m[0mlookfor[0m [0;32mimport[0m [0mlookfor[0m[0;34m[0m[0;34m[0m[0m
[1;32m    137[0m [0;34m[0m[0m

[0;32m/opt/hostedtoolcache/Python/3.8.11/x64/lib/python3.8/site-packages/skimage/data/__init__.py[0m in [0;36m<module>[0;34m[0m
[1;32m     62[0m [0;34m[0m[0m
[1;32m     63[0m [0;32mtry[0m[0;34m:[0m[0;34m[0m[0;34m[0m[0m
[0;32m---> 64[0;31m     [0;32mfrom[0m [0mpooch[0m[0;34m.[0m[0mutils[0m [0;32mimport[0m [0mfile_hash[0m[0;34m[0m[0;34m[0m[0m
[0m[1;32m     65[0m [0;32mexcept[0m [0mModuleNotFoundError[0m[0;34m:[0m[0;34m[0m[0;34m[0m[0m
[1;32m     66[0m     [0;31m# Function taken from[0m[0;34m[0m[0;34m[0m[0;34m[0m[0m

[0;31mImportError[0m: cannot import name 'file_hash' from 'pooch.utils' (/opt/hostedtoolcache/Python/3.8.11/x64/lib/python3.8/site-packages/pooch/utils.py)
ImportError: cannot import name 'file_hash' from 'pooch.utils' (/opt/hostedtoolcache/Python/3.8.11/x64/lib/python3.8/site-packages/pooch/utils.py)

